<?xml version="1.0"?>
<robot name="gripper" xmlns:xacro="http://wiki.ros.org/xacro">

  <xacro:macro name="gripper" params="">

    <!-- Base de la pinza -->
    <link name="base_pinza_link">
      <collision name="base_pinza_collision">
        <origin rpy="0 0 0" xyz="0 0 0"/>
        <geometry>
          <box size="0.8 0.3 0.05"/>
        </geometry>
      </collision>
      <visual name="base_pinza">
        <origin rpy="0 0 0" xyz="0 0 0"/>
        <geometry>
          <box size="0.8 0.3 0.05"/>
        </geometry>
      </visual>
      <inertial>
        <mass value="1.0"/>
        <origin xyz="0 0 0" rpy="0 0 0"/>
        <inertia ixx="0.00771" ixy="0" ixz="0" iyy="0.05354" iyz="0" izz="0.06083"/>
      </inertial>
    </link>

    <joint name="base_pinza_link_joint" type="fixed">
      <origin rpy="0.00000 0.00000 0.00000" xyz="0.00000 0.00000 -0.05000"/>
      <parent link="soporte_pinza_link"/>
      <child link="base_pinza_link"/>
    </joint>

    <!-- Pinza 1 -->
    <joint name="5_pinza" type="prismatic">
      <limit lower="0.0" upper="0.24" effort="500.0" velocity="1.0"/>
      <origin rpy="3.14159 0 3.14159" xyz="0.37 0 -0.12"/>
      <parent link="base_pinza_link"/>
      <child link="pinza_1_link"/>
      <axis xyz="1 0 0"/>
    </joint>

    <link name="pinza_1_link">
      <collision name="pinza_1_collision">
        <origin rpy="0 0 0" xyz="0 0 0"/>
        <geometry>
          <box size="0.05 0.2 0.2"/>
        </geometry>
      </collision>
      <visual name="pinza_1">
        <origin rpy="0 0 0" xyz="0 0 0"/>
        <geometry>
          <box size="0.05 0.2 0.2"/>
        </geometry>
      </visual>
      <inertial>
        <mass value="0.5"/>
        <origin xyz="0 0 0" rpy="0 0 0"/>
        <inertia ixx="0.00333" ixy="0" ixz="0" iyy="0.00177" iyz="0" izz="0.00177"/>
      </inertial>
    </link>

    <!-- Pinza 2 -->
    <joint name="6_pinza" type="prismatic">
      <limit lower="0.0" upper="0.24" effort="500.0" velocity="1.0"/>
      <origin rpy="0 0 0" xyz="-0.37 0 -0.12"/>
      <parent link="base_pinza_link"/>
      <child link="pinza_2_link"/>
      <axis xyz="1 0 0"/>
    </joint>

    <link name="pinza_2_link">
      <collision name="pinza_2_collision">
        <origin rpy="0 0 0" xyz="0 0 0"/>
        <geometry>
          <box size="0.05 0.2 0.2"/>
        </geometry>
      </collision>
      <visual name="pinza_2">
        <origin rpy="0 0 0" xyz="0 0 0"/>
        <geometry>
          <box size="0.05 0.2 0.2"/>
        </geometry>
      </visual>
      <inertial>
        <mass value="0.5"/>
        <origin xyz="0 0 0" rpy="0 0 0"/>
        <inertia ixx="0.00333" ixy="0" ixz="0" iyy="0.00177" iyz="0" izz="0.00177"/>
      </inertial>
    </link>

  </xacro:macro>

</robot>
